2025-09-30 22:16:12 UTC
Windows-11-10.0.26100-SP0
Ren'Py 8.4.1.25072401

Early init took 59 ms
Loading error handling took 171 ms
Loading script took 2580 ms
Loading save slot metadata took 43 ms
Loading persistent took 0 ms
Running init code took 249 ms
Loading analysis data took 0 ms
Analyze and compile ATL took 8 ms
Reloading save slot metadata took 19 ms
Backing up script files to 'C:\\Users\\alynt\\AppData\\Roaming/RenPy/backups\\Three-s-A-Crowd-':
Dump and make backups took 58 ms
Cleaning cache took 0 ms
Making clean stores took 0 ms
Initial gc took 65 ms
DPI scale factor: 1.000000
nvdrs: Loaded, about to disable thread optimizations.
nvdrs: Disabled thread optimizations.
Creating interface object took 741 ms
Init translation took 0 ms
Cleaning stores took 0 ms
Load screen analysis took 0 ms
Analyze screens took 43 ms
Save screen analysis took 20 ms
Save pyanalysis took 5 ms
Save bytecode took 0 ms

Full traceback:
  File "renpy/main.py", line 614, in main
    run(restart)
    ~~~^^^^^^^^^
  File "renpy/main.py", line 95, in run
    raise renpy.game.QuitException()
renpy.game.QuitException

During handling of the above exception, another exception occurred:

Traceback (most recent call last):
  File "renpy/bootstrap.py", line 376, in bootstrap
    renpy.main.main()
    ~~~~~~~~~~~~~~~^^
  File "renpy/main.py", line 626, in main
    renpy.persistent.update(True)
    ~~~~~~~~~~~~~~~~~~~~~~~^^^^^^
  File "renpy/persistent.py", line 461, in update
    save()
    ~~~~^^
  File "renpy/persistent.py", line 484, in save
    renpy.loadsave.location.save_persistent(compressed)
    ~~~~~~~~~~~~~~~~~~~~~~~~~~~~~~~~~~~~~~~^^^^^^^^^^^^
  File "renpy/savelocation.py", line 619, in save_persistent
    l.save_persistent(data)
    ~~~~~~~~~~~~~~~~~^^^^^^
  File "renpy/savelocation.py", line 431, in save_persistent
    safe_rename(fn_new, fn)
    ~~~~~~~~~~~^^^^^^^^^^^^
  File "renpy/loadsave.py", line 60, in safe_rename
    os.unlink(new)
    ~~~~~~~~~^^^^^
PermissionError: [WinError 32] The process cannot access the file because it is being used by another process: 'C:\\Users\\alynt\\AppData\\Roaming/RenPy/ThreesACrowd-1757774791/sync\\persistent'

After initialization, but before game start.
renpy.game.QuitException

During handling of the above exception, another exception occurred:

PermissionError: [WinError 32] The process cannot access the file because it is being used by another process: 'C:\\Users\\alynt\\AppData\\Roaming/RenPy/ThreesACrowd-1757774791/sync\\persistent'
